<?xml version="1.0" encoding="UTF-8"?>
<testng-results ignored="0" total="5" passed="1" failed="4" skipped="0">
  <reporter-output>
    <line>
      <![CDATA[test has been failed]]>
    </line>
    <line>
      <![CDATA[test has been failed]]>
    </line>
    <line>
      <![CDATA[test has been failed]]>
    </line>
    <line>
      <![CDATA[test has been failed]]>
    </line>
  </reporter-output>
  <suite started-at="2021-07-02T09:09:32 IST" name="Default suite" finished-at="2021-07-02T09:10:12 IST" duration-ms="40104">
    <groups>
    </groups>
    <test started-at="2021-07-02T09:09:32 IST" name="Default test" finished-at="2021-07-02T09:10:12 IST" duration-ms="40104">
      <class name="takeSSdynamically.TestScreenShots">
        <test-method is-config="true" signature="setUp()[pri:0, instance:takeSSdynamically.TestScreenShots@149e0f5d]" started-at="2021-07-02T09:09:32 IST" name="setUp" finished-at="2021-07-02T09:09:41 IST" duration-ms="8653" status="PASS">
          <reporter-output>
          </reporter-output>
        </test-method> <!-- setUp -->
        <test-method signature="verifyTitle()[pri:0, instance:takeSSdynamically.TestScreenShots@149e0f5d]" started-at="2021-07-02T09:09:41 IST" name="verifyTitle" finished-at="2021-07-02T09:09:41 IST" duration-ms="57" status="PASS">
          <reporter-output>
          </reporter-output>
        </test-method> <!-- verifyTitle -->
        <test-method is-config="true" signature="tearDown()[pri:0, instance:takeSSdynamically.TestScreenShots@149e0f5d]" started-at="2021-07-02T09:09:41 IST" name="tearDown" finished-at="2021-07-02T09:09:42 IST" duration-ms="1176" status="PASS">
          <reporter-output>
          </reporter-output>
        </test-method> <!-- tearDown -->
        <test-method is-config="true" signature="setUp()[pri:0, instance:takeSSdynamically.TestScreenShots@149e0f5d]" started-at="2021-07-02T09:09:42 IST" name="setUp" finished-at="2021-07-02T09:09:49 IST" duration-ms="6784" status="PASS">
          <reporter-output>
          </reporter-output>
        </test-method> <!-- setUp -->
        <test-method signature="verifyTitle2()[pri:0, instance:takeSSdynamically.TestScreenShots@149e0f5d]" started-at="2021-07-02T09:09:49 IST" name="verifyTitle2" finished-at="2021-07-02T09:09:49 IST" duration-ms="41" status="FAIL">
          <exception class="java.lang.AssertionError">
            <message>
              <![CDATA[expected [actiTIME - Logi] but found [actiTIME - Login]]]>
            </message>
            <full-stacktrace>
              <![CDATA[java.lang.AssertionError: expected [actiTIME - Logi] but found [actiTIME - Login]
at org.testng.Assert.fail(Assert.java:99)
at org.testng.Assert.failNotEquals(Assert.java:1037)
at org.testng.Assert.assertEqualsImpl(Assert.java:140)
at org.testng.Assert.assertEquals(Assert.java:122)
at org.testng.Assert.assertEquals(Assert.java:629)
at org.testng.Assert.assertEquals(Assert.java:639)
at takeSSdynamically.TestScreenShots.verifyTitle2(TestScreenShots.java:37)
at java.base/jdk.internal.reflect.NativeMethodAccessorImpl.invoke0(Native Method)
at java.base/jdk.internal.reflect.NativeMethodAccessorImpl.invoke(NativeMethodAccessorImpl.java:64)
at java.base/jdk.internal.reflect.DelegatingMethodAccessorImpl.invoke(DelegatingMethodAccessorImpl.java:43)
at java.base/java.lang.reflect.Method.invoke(Method.java:564)
at org.testng.internal.MethodInvocationHelper.invokeMethod(MethodInvocationHelper.java:133)
at org.testng.internal.TestInvoker.invokeMethod(TestInvoker.java:598)
at org.testng.internal.TestInvoker.invokeTestMethod(TestInvoker.java:173)
at org.testng.internal.MethodRunner.runInSequence(MethodRunner.java:46)
at org.testng.internal.TestInvoker$MethodInvocationAgent.invoke(TestInvoker.java:824)
at org.testng.internal.TestInvoker.invokeTestMethods(TestInvoker.java:146)
at org.testng.internal.TestMethodWorker.invokeTestMethods(TestMethodWorker.java:146)
at org.testng.internal.TestMethodWorker.run(TestMethodWorker.java:128)
at java.base/java.util.ArrayList.forEach(ArrayList.java:1511)
at org.testng.TestRunner.privateRun(TestRunner.java:794)
at org.testng.TestRunner.run(TestRunner.java:596)
at org.testng.SuiteRunner.runTest(SuiteRunner.java:377)
at org.testng.SuiteRunner.runSequentially(SuiteRunner.java:371)
at org.testng.SuiteRunner.privateRun(SuiteRunner.java:332)
at org.testng.SuiteRunner.run(SuiteRunner.java:276)
at org.testng.SuiteRunnerWorker.runSuite(SuiteRunnerWorker.java:53)
at org.testng.SuiteRunnerWorker.run(SuiteRunnerWorker.java:96)
at org.testng.TestNG.runSuitesSequentially(TestNG.java:1212)
at org.testng.TestNG.runSuitesLocally(TestNG.java:1134)
at org.testng.TestNG.runSuites(TestNG.java:1063)
at org.testng.TestNG.run(TestNG.java:1031)
at org.testng.remote.AbstractRemoteTestNG.run(AbstractRemoteTestNG.java:115)
at org.testng.remote.RemoteTestNG.initAndRun(RemoteTestNG.java:251)
at org.testng.remote.RemoteTestNG.main(RemoteTestNG.java:77)
]]>
            </full-stacktrace>
          </exception> <!-- java.lang.AssertionError -->
          <reporter-output>
            <line>
              <![CDATA[test has been failed]]>
            </line>
          </reporter-output>
        </test-method> <!-- verifyTitle2 -->
        <test-method is-config="true" signature="tearDown()[pri:0, instance:takeSSdynamically.TestScreenShots@149e0f5d]" started-at="2021-07-02T09:09:49 IST" name="tearDown" finished-at="2021-07-02T09:09:50 IST" duration-ms="1113" status="PASS">
          <reporter-output>
          </reporter-output>
        </test-method> <!-- tearDown -->
        <test-method is-config="true" signature="setUp()[pri:0, instance:takeSSdynamically.TestScreenShots@149e0f5d]" started-at="2021-07-02T09:09:50 IST" name="setUp" finished-at="2021-07-02T09:09:56 IST" duration-ms="6269" status="PASS">
          <reporter-output>
          </reporter-output>
        </test-method> <!-- setUp -->
        <test-method signature="verifyTitle3()[pri:0, instance:takeSSdynamically.TestScreenShots@149e0f5d]" started-at="2021-07-02T09:09:56 IST" name="verifyTitle3" finished-at="2021-07-02T09:09:57 IST" duration-ms="26" status="FAIL">
          <exception class="java.lang.AssertionError">
            <message>
              <![CDATA[expected [actiTIME - Logi] but found [actiTIME - Login]]]>
            </message>
            <full-stacktrace>
              <![CDATA[java.lang.AssertionError: expected [actiTIME - Logi] but found [actiTIME - Login]
at org.testng.Assert.fail(Assert.java:99)
at org.testng.Assert.failNotEquals(Assert.java:1037)
at org.testng.Assert.assertEqualsImpl(Assert.java:140)
at org.testng.Assert.assertEquals(Assert.java:122)
at org.testng.Assert.assertEquals(Assert.java:629)
at org.testng.Assert.assertEquals(Assert.java:639)
at takeSSdynamically.TestScreenShots.verifyTitle3(TestScreenShots.java:44)
at java.base/jdk.internal.reflect.NativeMethodAccessorImpl.invoke0(Native Method)
at java.base/jdk.internal.reflect.NativeMethodAccessorImpl.invoke(NativeMethodAccessorImpl.java:64)
at java.base/jdk.internal.reflect.DelegatingMethodAccessorImpl.invoke(DelegatingMethodAccessorImpl.java:43)
at java.base/java.lang.reflect.Method.invoke(Method.java:564)
at org.testng.internal.MethodInvocationHelper.invokeMethod(MethodInvocationHelper.java:133)
at org.testng.internal.TestInvoker.invokeMethod(TestInvoker.java:598)
at org.testng.internal.TestInvoker.invokeTestMethod(TestInvoker.java:173)
at org.testng.internal.MethodRunner.runInSequence(MethodRunner.java:46)
at org.testng.internal.TestInvoker$MethodInvocationAgent.invoke(TestInvoker.java:824)
at org.testng.internal.TestInvoker.invokeTestMethods(TestInvoker.java:146)
at org.testng.internal.TestMethodWorker.invokeTestMethods(TestMethodWorker.java:146)
at org.testng.internal.TestMethodWorker.run(TestMethodWorker.java:128)
at java.base/java.util.ArrayList.forEach(ArrayList.java:1511)
at org.testng.TestRunner.privateRun(TestRunner.java:794)
at org.testng.TestRunner.run(TestRunner.java:596)
at org.testng.SuiteRunner.runTest(SuiteRunner.java:377)
at org.testng.SuiteRunner.runSequentially(SuiteRunner.java:371)
at org.testng.SuiteRunner.privateRun(SuiteRunner.java:332)
at org.testng.SuiteRunner.run(SuiteRunner.java:276)
at org.testng.SuiteRunnerWorker.runSuite(SuiteRunnerWorker.java:53)
at org.testng.SuiteRunnerWorker.run(SuiteRunnerWorker.java:96)
at org.testng.TestNG.runSuitesSequentially(TestNG.java:1212)
at org.testng.TestNG.runSuitesLocally(TestNG.java:1134)
at org.testng.TestNG.runSuites(TestNG.java:1063)
at org.testng.TestNG.run(TestNG.java:1031)
at org.testng.remote.AbstractRemoteTestNG.run(AbstractRemoteTestNG.java:115)
at org.testng.remote.RemoteTestNG.initAndRun(RemoteTestNG.java:251)
at org.testng.remote.RemoteTestNG.main(RemoteTestNG.java:77)
]]>
            </full-stacktrace>
          </exception> <!-- java.lang.AssertionError -->
          <reporter-output>
            <line>
              <![CDATA[test has been failed]]>
            </line>
          </reporter-output>
        </test-method> <!-- verifyTitle3 -->
        <test-method is-config="true" signature="tearDown()[pri:0, instance:takeSSdynamically.TestScreenShots@149e0f5d]" started-at="2021-07-02T09:09:57 IST" name="tearDown" finished-at="2021-07-02T09:09:58 IST" duration-ms="1081" status="PASS">
          <reporter-output>
          </reporter-output>
        </test-method> <!-- tearDown -->
        <test-method is-config="true" signature="setUp()[pri:0, instance:takeSSdynamically.TestScreenShots@149e0f5d]" started-at="2021-07-02T09:09:58 IST" name="setUp" finished-at="2021-07-02T09:10:04 IST" duration-ms="6388" status="PASS">
          <reporter-output>
          </reporter-output>
        </test-method> <!-- setUp -->
        <test-method signature="verifyTitle4()[pri:0, instance:takeSSdynamically.TestScreenShots@149e0f5d]" started-at="2021-07-02T09:10:04 IST" name="verifyTitle4" finished-at="2021-07-02T09:10:04 IST" duration-ms="23" status="FAIL">
          <exception class="java.lang.AssertionError">
            <message>
              <![CDATA[expected [actiTIME - Logi] but found [actiTIME - Login]]]>
            </message>
            <full-stacktrace>
              <![CDATA[java.lang.AssertionError: expected [actiTIME - Logi] but found [actiTIME - Login]
at org.testng.Assert.fail(Assert.java:99)
at org.testng.Assert.failNotEquals(Assert.java:1037)
at org.testng.Assert.assertEqualsImpl(Assert.java:140)
at org.testng.Assert.assertEquals(Assert.java:122)
at org.testng.Assert.assertEquals(Assert.java:629)
at org.testng.Assert.assertEquals(Assert.java:639)
at takeSSdynamically.TestScreenShots.verifyTitle4(TestScreenShots.java:51)
at java.base/jdk.internal.reflect.NativeMethodAccessorImpl.invoke0(Native Method)
at java.base/jdk.internal.reflect.NativeMethodAccessorImpl.invoke(NativeMethodAccessorImpl.java:64)
at java.base/jdk.internal.reflect.DelegatingMethodAccessorImpl.invoke(DelegatingMethodAccessorImpl.java:43)
at java.base/java.lang.reflect.Method.invoke(Method.java:564)
at org.testng.internal.MethodInvocationHelper.invokeMethod(MethodInvocationHelper.java:133)
at org.testng.internal.TestInvoker.invokeMethod(TestInvoker.java:598)
at org.testng.internal.TestInvoker.invokeTestMethod(TestInvoker.java:173)
at org.testng.internal.MethodRunner.runInSequence(MethodRunner.java:46)
at org.testng.internal.TestInvoker$MethodInvocationAgent.invoke(TestInvoker.java:824)
at org.testng.internal.TestInvoker.invokeTestMethods(TestInvoker.java:146)
at org.testng.internal.TestMethodWorker.invokeTestMethods(TestMethodWorker.java:146)
at org.testng.internal.TestMethodWorker.run(TestMethodWorker.java:128)
at java.base/java.util.ArrayList.forEach(ArrayList.java:1511)
at org.testng.TestRunner.privateRun(TestRunner.java:794)
at org.testng.TestRunner.run(TestRunner.java:596)
at org.testng.SuiteRunner.runTest(SuiteRunner.java:377)
at org.testng.SuiteRunner.runSequentially(SuiteRunner.java:371)
at org.testng.SuiteRunner.privateRun(SuiteRunner.java:332)
at org.testng.SuiteRunner.run(SuiteRunner.java:276)
at org.testng.SuiteRunnerWorker.runSuite(SuiteRunnerWorker.java:53)
at org.testng.SuiteRunnerWorker.run(SuiteRunnerWorker.java:96)
at org.testng.TestNG.runSuitesSequentially(TestNG.java:1212)
at org.testng.TestNG.runSuitesLocally(TestNG.java:1134)
at org.testng.TestNG.runSuites(TestNG.java:1063)
at org.testng.TestNG.run(TestNG.java:1031)
at org.testng.remote.AbstractRemoteTestNG.run(AbstractRemoteTestNG.java:115)
at org.testng.remote.RemoteTestNG.initAndRun(RemoteTestNG.java:251)
at org.testng.remote.RemoteTestNG.main(RemoteTestNG.java:77)
]]>
            </full-stacktrace>
          </exception> <!-- java.lang.AssertionError -->
          <reporter-output>
            <line>
              <![CDATA[test has been failed]]>
            </line>
          </reporter-output>
        </test-method> <!-- verifyTitle4 -->
        <test-method is-config="true" signature="tearDown()[pri:0, instance:takeSSdynamically.TestScreenShots@149e0f5d]" started-at="2021-07-02T09:10:05 IST" name="tearDown" finished-at="2021-07-02T09:10:06 IST" duration-ms="1327" status="PASS">
          <reporter-output>
          </reporter-output>
        </test-method> <!-- tearDown -->
        <test-method is-config="true" signature="setUp()[pri:0, instance:takeSSdynamically.TestScreenShots@149e0f5d]" started-at="2021-07-02T09:10:06 IST" name="setUp" finished-at="2021-07-02T09:10:11 IST" duration-ms="4796" status="PASS">
          <reporter-output>
          </reporter-output>
        </test-method> <!-- setUp -->
        <test-method signature="verifyTitle5()[pri:0, instance:takeSSdynamically.TestScreenShots@149e0f5d]" started-at="2021-07-02T09:10:11 IST" name="verifyTitle5" finished-at="2021-07-02T09:10:11 IST" duration-ms="17" status="FAIL">
          <exception class="java.lang.AssertionError">
            <message>
              <![CDATA[expected [actiTIME - Logi] but found [actiTIME - Login]]]>
            </message>
            <full-stacktrace>
              <![CDATA[java.lang.AssertionError: expected [actiTIME - Logi] but found [actiTIME - Login]
at org.testng.Assert.fail(Assert.java:99)
at org.testng.Assert.failNotEquals(Assert.java:1037)
at org.testng.Assert.assertEqualsImpl(Assert.java:140)
at org.testng.Assert.assertEquals(Assert.java:122)
at org.testng.Assert.assertEquals(Assert.java:629)
at org.testng.Assert.assertEquals(Assert.java:639)
at takeSSdynamically.TestScreenShots.verifyTitle5(TestScreenShots.java:58)
at java.base/jdk.internal.reflect.NativeMethodAccessorImpl.invoke0(Native Method)
at java.base/jdk.internal.reflect.NativeMethodAccessorImpl.invoke(NativeMethodAccessorImpl.java:64)
at java.base/jdk.internal.reflect.DelegatingMethodAccessorImpl.invoke(DelegatingMethodAccessorImpl.java:43)
at java.base/java.lang.reflect.Method.invoke(Method.java:564)
at org.testng.internal.MethodInvocationHelper.invokeMethod(MethodInvocationHelper.java:133)
at org.testng.internal.TestInvoker.invokeMethod(TestInvoker.java:598)
at org.testng.internal.TestInvoker.invokeTestMethod(TestInvoker.java:173)
at org.testng.internal.MethodRunner.runInSequence(MethodRunner.java:46)
at org.testng.internal.TestInvoker$MethodInvocationAgent.invoke(TestInvoker.java:824)
at org.testng.internal.TestInvoker.invokeTestMethods(TestInvoker.java:146)
at org.testng.internal.TestMethodWorker.invokeTestMethods(TestMethodWorker.java:146)
at org.testng.internal.TestMethodWorker.run(TestMethodWorker.java:128)
at java.base/java.util.ArrayList.forEach(ArrayList.java:1511)
at org.testng.TestRunner.privateRun(TestRunner.java:794)
at org.testng.TestRunner.run(TestRunner.java:596)
at org.testng.SuiteRunner.runTest(SuiteRunner.java:377)
at org.testng.SuiteRunner.runSequentially(SuiteRunner.java:371)
at org.testng.SuiteRunner.privateRun(SuiteRunner.java:332)
at org.testng.SuiteRunner.run(SuiteRunner.java:276)
at org.testng.SuiteRunnerWorker.runSuite(SuiteRunnerWorker.java:53)
at org.testng.SuiteRunnerWorker.run(SuiteRunnerWorker.java:96)
at org.testng.TestNG.runSuitesSequentially(TestNG.java:1212)
at org.testng.TestNG.runSuitesLocally(TestNG.java:1134)
at org.testng.TestNG.runSuites(TestNG.java:1063)
at org.testng.TestNG.run(TestNG.java:1031)
at org.testng.remote.AbstractRemoteTestNG.run(AbstractRemoteTestNG.java:115)
at org.testng.remote.RemoteTestNG.initAndRun(RemoteTestNG.java:251)
at org.testng.remote.RemoteTestNG.main(RemoteTestNG.java:77)
]]>
            </full-stacktrace>
          </exception> <!-- java.lang.AssertionError -->
          <reporter-output>
            <line>
              <![CDATA[test has been failed]]>
            </line>
          </reporter-output>
        </test-method> <!-- verifyTitle5 -->
        <test-method is-config="true" signature="tearDown()[pri:0, instance:takeSSdynamically.TestScreenShots@149e0f5d]" started-at="2021-07-02T09:10:11 IST" name="tearDown" finished-at="2021-07-02T09:10:12 IST" duration-ms="1028" status="PASS">
          <reporter-output>
          </reporter-output>
        </test-method> <!-- tearDown -->
      </class> <!-- takeSSdynamically.TestScreenShots -->
    </test> <!-- Default test -->
  </suite> <!-- Default suite -->
</testng-results>
